2025-03-09 22:13:00,821 INFO    Thread-21 (_run_job):19348 [wandb_init.py:setup_run_log_directory():647] Logging user logs to c:\Users\prajv\Downloads\ass1\DA6401_ASSIGNMENT1\wandb\run-20250309_221300-8vvffu15\logs\debug.log
2025-03-09 22:13:00,829 INFO    Thread-21 (_run_job):19348 [wandb_init.py:setup_run_log_directory():648] Logging internal logs to c:\Users\prajv\Downloads\ass1\DA6401_ASSIGNMENT1\wandb\run-20250309_221300-8vvffu15\logs\debug-internal.log
2025-03-09 22:13:00,829 INFO    Thread-21 (_run_job):19348 [wandb_init.py:init():761] calling init triggers
2025-03-09 22:13:00,829 INFO    Thread-21 (_run_job):19348 [wandb_init.py:init():766] wandb.init called with sweep_config: {'activationFunc': 'sigmoid', 'batchSize': 116, 'hiddenLayer_Size': 64, 'learningRate': 0.0001, 'num_epochs': 5, 'num_hiddenLayers': 3, 'optimizer': 'adam', 'weightDecay': 0, 'weightInit': 'random'}
config: {'num_epochs': 10, 'num_hiddenLayers': 3, 'hiddenLayer_Size': 40, 'weightDecay': 0, 'learningRate': 0.001, 'optimizer': 'Nesterov_Accelerated_GD', 'batchSize': 32, 'weightInit': 'xavier', 'activationFunc': 'sigmoid', '_wandb': {}}
2025-03-09 22:13:00,829 INFO    Thread-21 (_run_job):19348 [wandb_init.py:init():776] wandb.init() called while a run is active
2025-03-09 22:13:00,993 INFO    Thread-21 (_run_job):19348 [wandb_run.py:_finish():2112] finishing run da6401-assignments/assignment1/8vvffu15
2025-03-09 22:13:00,996 ERROR   Thread-21 (_run_job):19348 [jupyter.py:save_history():450] Run pip install nbformat to save notebook history
2025-03-09 22:13:00,996 INFO    Thread-21 (_run_job):19348 [jupyter.py:save_ipynb():386] not saving jupyter notebook
2025-03-09 22:13:00,996 INFO    Thread-21 (_run_job):19348 [wandb_init.py:_jupyter_teardown():581] cleaning up jupyter logic
2025-03-09 22:13:00,997 INFO    Thread-21 (_run_job):19348 [wandb_run.py:_atexit_cleanup():2340] got exitcode: 1
2025-03-09 22:13:00,997 INFO    Thread-21 (_run_job):19348 [wandb_run.py:_restore():2322] restore
2025-03-09 22:13:00,997 INFO    Thread-21 (_run_job):19348 [wandb_run.py:_restore():2328] restore done
2025-03-09 22:13:03,627 INFO    Thread-21 (_run_job):19348 [wandb_run.py:_footer_history_summary_info():3956] rendering history
2025-03-09 22:13:03,627 INFO    Thread-21 (_run_job):19348 [wandb_run.py:_footer_history_summary_info():3988] rendering summary
2025-03-09 22:13:03,627 INFO    Thread-21 (_run_job):19348 [wandb_run.py:_footer_sync_info():3917] logging synced files
2025-03-09 22:13:03,631 ERROR   MainThread:19348 [pyagent.py:_run_jobs_from_queue():234] Run 8vvffu15 errored:
Traceback (most recent call last):
  File "c:\Python312\Lib\site-packages\wandb\agents\pyagent.py", line 306, in _run_job
    self._function()
  File "C:\Users\prajv\AppData\Local\Temp\ipykernel_19348\1058529509.py", line 36, in sweep_hyperParameters
    model.train(x_train, y_train, x_val, y_val, num_epochs, learningRate, optimizer, batchSize)
  File "C:\Users\prajv\AppData\Local\Temp\ipykernel_19348\4057043383.py", line 60, in train
    self.forward(x_batch)
  File "C:\Users\prajv\AppData\Local\Temp\ipykernel_19348\4057043383.py", line 113, in forward
    output = self.softmax(np.dot(x, self.weights[-1]) + self.biases[-1])
                          ^^^^^^^^^^^^^^^^^^^^^^^^^^^
ValueError: shapes (64,116) and (64,10) not aligned: 116 (dim 1) != 64 (dim 0)

2025-03-09 22:13:03,631 ERROR   MainThread:19348 [pyagent.py:_run_jobs_from_queue():245] Detected 3 failed runs in the first 60 seconds, killing sweep.
