2025-03-09 19:47:47,554 INFO    MainThread:13900 [wandb_setup.py:_flush():67] Current SDK version is 0.19.8
2025-03-09 19:47:47,554 INFO    MainThread:13900 [wandb_setup.py:_flush():67] Configure stats pid to 13900
2025-03-09 19:47:47,554 INFO    MainThread:13900 [wandb_setup.py:_flush():67] Loading settings from C:\Users\prajv\.config\wandb\settings
2025-03-09 19:47:47,554 INFO    MainThread:13900 [wandb_setup.py:_flush():67] Loading settings from c:\Users\prajv\Downloads\ass1\DA6401_ASSIGNMENT1\wandb\settings
2025-03-09 19:47:47,554 INFO    MainThread:13900 [wandb_setup.py:_flush():67] Loading settings from environment variables
2025-03-09 19:47:47,554 INFO    MainThread:13900 [wandb_init.py:setup_run_log_directory():647] Logging user logs to c:\Users\prajv\Downloads\ass1\DA6401_ASSIGNMENT1\wandb\run-20250309_194747-zhc4c9et\logs\debug.log
2025-03-09 19:47:47,554 INFO    MainThread:13900 [wandb_init.py:setup_run_log_directory():648] Logging internal logs to c:\Users\prajv\Downloads\ass1\DA6401_ASSIGNMENT1\wandb\run-20250309_194747-zhc4c9et\logs\debug-internal.log
2025-03-09 19:47:47,554 INFO    MainThread:13900 [wandb_init.py:init():761] calling init triggers
2025-03-09 19:47:47,554 INFO    MainThread:13900 [wandb_init.py:init():766] wandb.init called with sweep_config: {}
config: {'_wandb': {}}
2025-03-09 19:47:47,554 INFO    MainThread:13900 [wandb_init.py:init():776] wandb.init() called while a run is active
2025-03-09 19:47:47,555 ERROR   MainThread:13900 [wandb_init.py:init():1478] error in wandb.init()
Traceback (most recent call last):
  File "c:\Python312\Lib\site-packages\wandb\sdk\wandb_init.py", line 1468, in init
    return wi.init(run_settings, run_config)
           ^^^^^^^^^^^^^^^^^^^^^^^^^^^^^^^^^
  File "c:\Python312\Lib\site-packages\wandb\sdk\wandb_init.py", line 779, in init
    with telemetry.context() as tel:
         ^^^^^^^^^^^^^^^^^^^
  File "c:\Python312\Lib\site-packages\wandb\sdk\lib\telemetry.py", line 42, in __exit__
    self._run._telemetry_callback(self._obj)
  File "c:\Python312\Lib\site-packages\wandb\sdk\wandb_run.py", line 749, in _telemetry_callback
    self._telemetry_flush()
  File "c:\Python312\Lib\site-packages\wandb\sdk\wandb_run.py", line 762, in _telemetry_flush
    self._backend.interface._publish_telemetry(self._telemetry_obj)
  File "c:\Python312\Lib\site-packages\wandb\sdk\interface\interface_shared.py", line 60, in _publish_telemetry
    self._publish(rec)
  File "c:\Python312\Lib\site-packages\wandb\sdk\interface\interface_sock.py", line 39, in _publish
    self._sock_client.send_record_publish(record)
  File "c:\Python312\Lib\site-packages\wandb\sdk\lib\sock_client.py", line 174, in send_record_publish
    self.send_server_request(server_req)
  File "c:\Python312\Lib\site-packages\wandb\sdk\lib\sock_client.py", line 154, in send_server_request
    self._send_message(msg)
  File "c:\Python312\Lib\site-packages\wandb\sdk\lib\sock_client.py", line 151, in _send_message
    self._sendall_with_error_handle(header + data)
  File "c:\Python312\Lib\site-packages\wandb\sdk\lib\sock_client.py", line 130, in _sendall_with_error_handle
    sent = self._sock.send(data)
           ^^^^^^^^^^^^^^^^^^^^^
ConnectionAbortedError: [WinError 10053] An established connection was aborted by the software in your host machine
2025-03-09 19:47:47,914 INFO    MainThread:13900 [jupyter.py:save_ipynb():386] not saving jupyter notebook
2025-03-09 19:47:47,914 INFO    MainThread:13900 [wandb_init.py:_pause_backend():564] pausing backend
2025-03-09 19:47:47,914 ERROR   MainThread:13900 [redirect.py:_on_write():661] error in stdout callback
Traceback (most recent call last):
  File "C:\Users\prajv\AppData\Roaming\Python\Python312\site-packages\IPython\core\events.py", line 82, in trigger
    func(*args, **kwargs)
  File "c:\Python312\Lib\site-packages\wandb\sdk\wandb_init.py", line 565, in _pause_backend
    self.backend.interface.publish_pause()
  File "c:\Python312\Lib\site-packages\wandb\sdk\interface\interface.py", line 769, in publish_pause
    self._publish_pause(pause)
  File "c:\Python312\Lib\site-packages\wandb\sdk\interface\interface_shared.py", line 289, in _publish_pause
    self._publish(rec)
  File "c:\Python312\Lib\site-packages\wandb\sdk\interface\interface_sock.py", line 39, in _publish
    self._sock_client.send_record_publish(record)
  File "c:\Python312\Lib\site-packages\wandb\sdk\lib\sock_client.py", line 174, in send_record_publish
    self.send_server_request(server_req)
  File "c:\Python312\Lib\site-packages\wandb\sdk\lib\sock_client.py", line 154, in send_server_request
    self._send_message(msg)
  File "c:\Python312\Lib\site-packages\wandb\sdk\lib\sock_client.py", line 151, in _send_message
    self._sendall_with_error_handle(header + data)
  File "c:\Python312\Lib\site-packages\wandb\sdk\lib\sock_client.py", line 130, in _sendall_with_error_handle
    sent = self._sock.send(data)
           ^^^^^^^^^^^^^^^^^^^^^
ConnectionAbortedError: [WinError 10053] An established connection was aborted by the software in your host machine

During handling of the above exception, another exception occurred:

Traceback (most recent call last):
  File "c:\Python312\Lib\site-packages\wandb\sdk\lib\redirect.py", line 659, in _on_write
    cb(written_data)
  File "c:\Python312\Lib\site-packages\wandb\sdk\wandb_run.py", line 2296, in <lambda>
    lambda data: self._console_raw_callback("stdout", data),
                 ^^^^^^^^^^^^^^^^^^^^^^^^^^^^^^^^^^^^^^^^^^
  File "c:\Python312\Lib\site-packages\wandb\sdk\wandb_run.py", line 401, in wrapper_fn
    return func(self, *args, **kwargs)
           ^^^^^^^^^^^^^^^^^^^^^^^^^^^
  File "c:\Python312\Lib\site-packages\wandb\sdk\wandb_run.py", line 1444, in _console_raw_callback
    self._backend.interface.publish_output_raw(name, data)
  File "c:\Python312\Lib\site-packages\wandb\sdk\interface\interface.py", line 761, in publish_output_raw
    self._publish_output_raw(o)
  File "c:\Python312\Lib\site-packages\wandb\sdk\interface\interface_shared.py", line 38, in _publish_output_raw
    self._publish(rec)
  File "c:\Python312\Lib\site-packages\wandb\sdk\interface\interface_sock.py", line 39, in _publish
    self._sock_client.send_record_publish(record)
  File "c:\Python312\Lib\site-packages\wandb\sdk\lib\sock_client.py", line 174, in send_record_publish
    self.send_server_request(server_req)
  File "c:\Python312\Lib\site-packages\wandb\sdk\lib\sock_client.py", line 154, in send_server_request
    self._send_message(msg)
  File "c:\Python312\Lib\site-packages\wandb\sdk\lib\sock_client.py", line 151, in _send_message
    self._sendall_with_error_handle(header + data)
  File "c:\Python312\Lib\site-packages\wandb\sdk\lib\sock_client.py", line 130, in _sendall_with_error_handle
    sent = self._sock.send(data)
           ^^^^^^^^^^^^^^^^^^^^^
ConnectionAbortedError: [WinError 10053] An established connection was aborted by the software in your host machine
2025-03-09 19:47:47,921 ERROR   MainThread:13900 [redirect.py:_on_write():661] error in stdout callback
Traceback (most recent call last):
  File "C:\Users\prajv\AppData\Roaming\Python\Python312\site-packages\IPython\core\events.py", line 82, in trigger
    func(*args, **kwargs)
  File "c:\Python312\Lib\site-packages\wandb\sdk\wandb_init.py", line 565, in _pause_backend
    self.backend.interface.publish_pause()
  File "c:\Python312\Lib\site-packages\wandb\sdk\interface\interface.py", line 769, in publish_pause
    self._publish_pause(pause)
  File "c:\Python312\Lib\site-packages\wandb\sdk\interface\interface_shared.py", line 289, in _publish_pause
    self._publish(rec)
  File "c:\Python312\Lib\site-packages\wandb\sdk\interface\interface_sock.py", line 39, in _publish
    self._sock_client.send_record_publish(record)
  File "c:\Python312\Lib\site-packages\wandb\sdk\lib\sock_client.py", line 174, in send_record_publish
    self.send_server_request(server_req)
  File "c:\Python312\Lib\site-packages\wandb\sdk\lib\sock_client.py", line 154, in send_server_request
    self._send_message(msg)
  File "c:\Python312\Lib\site-packages\wandb\sdk\lib\sock_client.py", line 151, in _send_message
    self._sendall_with_error_handle(header + data)
  File "c:\Python312\Lib\site-packages\wandb\sdk\lib\sock_client.py", line 130, in _sendall_with_error_handle
    sent = self._sock.send(data)
           ^^^^^^^^^^^^^^^^^^^^^
ConnectionAbortedError: [WinError 10053] An established connection was aborted by the software in your host machine

During handling of the above exception, another exception occurred:

Traceback (most recent call last):
  File "c:\Python312\Lib\site-packages\wandb\sdk\lib\redirect.py", line 659, in _on_write
    cb(written_data)
  File "c:\Python312\Lib\site-packages\wandb\sdk\wandb_run.py", line 2296, in <lambda>
    lambda data: self._console_raw_callback("stdout", data),
                 ^^^^^^^^^^^^^^^^^^^^^^^^^^^^^^^^^^^^^^^^^^
  File "c:\Python312\Lib\site-packages\wandb\sdk\wandb_run.py", line 401, in wrapper_fn
    return func(self, *args, **kwargs)
           ^^^^^^^^^^^^^^^^^^^^^^^^^^^
  File "c:\Python312\Lib\site-packages\wandb\sdk\wandb_run.py", line 1444, in _console_raw_callback
    self._backend.interface.publish_output_raw(name, data)
  File "c:\Python312\Lib\site-packages\wandb\sdk\interface\interface.py", line 761, in publish_output_raw
    self._publish_output_raw(o)
  File "c:\Python312\Lib\site-packages\wandb\sdk\interface\interface_shared.py", line 38, in _publish_output_raw
    self._publish(rec)
  File "c:\Python312\Lib\site-packages\wandb\sdk\interface\interface_sock.py", line 39, in _publish
    self._sock_client.send_record_publish(record)
  File "c:\Python312\Lib\site-packages\wandb\sdk\lib\sock_client.py", line 174, in send_record_publish
    self.send_server_request(server_req)
  File "c:\Python312\Lib\site-packages\wandb\sdk\lib\sock_client.py", line 154, in send_server_request
    self._send_message(msg)
  File "c:\Python312\Lib\site-packages\wandb\sdk\lib\sock_client.py", line 151, in _send_message
    self._sendall_with_error_handle(header + data)
  File "c:\Python312\Lib\site-packages\wandb\sdk\lib\sock_client.py", line 130, in _sendall_with_error_handle
    sent = self._sock.send(data)
           ^^^^^^^^^^^^^^^^^^^^^
ConnectionAbortedError: [WinError 10053] An established connection was aborted by the software in your host machine
2025-03-09 19:47:57,722 INFO    MainThread:13900 [wandb_init.py:_resume_backend():569] resuming backend
2025-03-09 19:47:57,722 ERROR   MainThread:13900 [redirect.py:_on_write():661] error in stdout callback
Traceback (most recent call last):
  File "C:\Users\prajv\AppData\Roaming\Python\Python312\site-packages\IPython\core\events.py", line 82, in trigger
    func(*args, **kwargs)
  File "c:\Python312\Lib\site-packages\wandb\sdk\wandb_init.py", line 570, in _resume_backend
    self.backend.interface.publish_resume()
  File "c:\Python312\Lib\site-packages\wandb\sdk\interface\interface.py", line 777, in publish_resume
    self._publish_resume(resume)
  File "c:\Python312\Lib\site-packages\wandb\sdk\interface\interface_shared.py", line 293, in _publish_resume
    self._publish(rec)
  File "c:\Python312\Lib\site-packages\wandb\sdk\interface\interface_sock.py", line 39, in _publish
    self._sock_client.send_record_publish(record)
  File "c:\Python312\Lib\site-packages\wandb\sdk\lib\sock_client.py", line 174, in send_record_publish
    self.send_server_request(server_req)
  File "c:\Python312\Lib\site-packages\wandb\sdk\lib\sock_client.py", line 154, in send_server_request
    self._send_message(msg)
  File "c:\Python312\Lib\site-packages\wandb\sdk\lib\sock_client.py", line 151, in _send_message
    self._sendall_with_error_handle(header + data)
  File "c:\Python312\Lib\site-packages\wandb\sdk\lib\sock_client.py", line 130, in _sendall_with_error_handle
    sent = self._sock.send(data)
           ^^^^^^^^^^^^^^^^^^^^^
ConnectionAbortedError: [WinError 10053] An established connection was aborted by the software in your host machine

During handling of the above exception, another exception occurred:

Traceback (most recent call last):
  File "c:\Python312\Lib\site-packages\wandb\sdk\lib\redirect.py", line 659, in _on_write
    cb(written_data)
  File "c:\Python312\Lib\site-packages\wandb\sdk\wandb_run.py", line 2296, in <lambda>
    lambda data: self._console_raw_callback("stdout", data),
                 ^^^^^^^^^^^^^^^^^^^^^^^^^^^^^^^^^^^^^^^^^^
  File "c:\Python312\Lib\site-packages\wandb\sdk\wandb_run.py", line 401, in wrapper_fn
    return func(self, *args, **kwargs)
           ^^^^^^^^^^^^^^^^^^^^^^^^^^^
  File "c:\Python312\Lib\site-packages\wandb\sdk\wandb_run.py", line 1444, in _console_raw_callback
    self._backend.interface.publish_output_raw(name, data)
  File "c:\Python312\Lib\site-packages\wandb\sdk\interface\interface.py", line 761, in publish_output_raw
    self._publish_output_raw(o)
  File "c:\Python312\Lib\site-packages\wandb\sdk\interface\interface_shared.py", line 38, in _publish_output_raw
    self._publish(rec)
  File "c:\Python312\Lib\site-packages\wandb\sdk\interface\interface_sock.py", line 39, in _publish
    self._sock_client.send_record_publish(record)
  File "c:\Python312\Lib\site-packages\wandb\sdk\lib\sock_client.py", line 174, in send_record_publish
    self.send_server_request(server_req)
  File "c:\Python312\Lib\site-packages\wandb\sdk\lib\sock_client.py", line 154, in send_server_request
    self._send_message(msg)
  File "c:\Python312\Lib\site-packages\wandb\sdk\lib\sock_client.py", line 151, in _send_message
    self._sendall_with_error_handle(header + data)
  File "c:\Python312\Lib\site-packages\wandb\sdk\lib\sock_client.py", line 130, in _sendall_with_error_handle
    sent = self._sock.send(data)
           ^^^^^^^^^^^^^^^^^^^^^
ConnectionAbortedError: [WinError 10053] An established connection was aborted by the software in your host machine
2025-03-09 19:47:57,726 ERROR   MainThread:13900 [redirect.py:_on_write():661] error in stdout callback
Traceback (most recent call last):
  File "C:\Users\prajv\AppData\Roaming\Python\Python312\site-packages\IPython\core\events.py", line 82, in trigger
    func(*args, **kwargs)
  File "c:\Python312\Lib\site-packages\wandb\sdk\wandb_init.py", line 570, in _resume_backend
    self.backend.interface.publish_resume()
  File "c:\Python312\Lib\site-packages\wandb\sdk\interface\interface.py", line 777, in publish_resume
    self._publish_resume(resume)
  File "c:\Python312\Lib\site-packages\wandb\sdk\interface\interface_shared.py", line 293, in _publish_resume
    self._publish(rec)
  File "c:\Python312\Lib\site-packages\wandb\sdk\interface\interface_sock.py", line 39, in _publish
    self._sock_client.send_record_publish(record)
  File "c:\Python312\Lib\site-packages\wandb\sdk\lib\sock_client.py", line 174, in send_record_publish
    self.send_server_request(server_req)
  File "c:\Python312\Lib\site-packages\wandb\sdk\lib\sock_client.py", line 154, in send_server_request
    self._send_message(msg)
  File "c:\Python312\Lib\site-packages\wandb\sdk\lib\sock_client.py", line 151, in _send_message
    self._sendall_with_error_handle(header + data)
  File "c:\Python312\Lib\site-packages\wandb\sdk\lib\sock_client.py", line 130, in _sendall_with_error_handle
    sent = self._sock.send(data)
           ^^^^^^^^^^^^^^^^^^^^^
ConnectionAbortedError: [WinError 10053] An established connection was aborted by the software in your host machine

During handling of the above exception, another exception occurred:

Traceback (most recent call last):
  File "c:\Python312\Lib\site-packages\wandb\sdk\lib\redirect.py", line 659, in _on_write
    cb(written_data)
  File "c:\Python312\Lib\site-packages\wandb\sdk\wandb_run.py", line 2296, in <lambda>
    lambda data: self._console_raw_callback("stdout", data),
                 ^^^^^^^^^^^^^^^^^^^^^^^^^^^^^^^^^^^^^^^^^^
  File "c:\Python312\Lib\site-packages\wandb\sdk\wandb_run.py", line 401, in wrapper_fn
    return func(self, *args, **kwargs)
           ^^^^^^^^^^^^^^^^^^^^^^^^^^^
  File "c:\Python312\Lib\site-packages\wandb\sdk\wandb_run.py", line 1444, in _console_raw_callback
    self._backend.interface.publish_output_raw(name, data)
  File "c:\Python312\Lib\site-packages\wandb\sdk\interface\interface.py", line 761, in publish_output_raw
    self._publish_output_raw(o)
  File "c:\Python312\Lib\site-packages\wandb\sdk\interface\interface_shared.py", line 38, in _publish_output_raw
    self._publish(rec)
  File "c:\Python312\Lib\site-packages\wandb\sdk\interface\interface_sock.py", line 39, in _publish
    self._sock_client.send_record_publish(record)
  File "c:\Python312\Lib\site-packages\wandb\sdk\lib\sock_client.py", line 174, in send_record_publish
    self.send_server_request(server_req)
  File "c:\Python312\Lib\site-packages\wandb\sdk\lib\sock_client.py", line 154, in send_server_request
    self._send_message(msg)
  File "c:\Python312\Lib\site-packages\wandb\sdk\lib\sock_client.py", line 151, in _send_message
    self._sendall_with_error_handle(header + data)
  File "c:\Python312\Lib\site-packages\wandb\sdk\lib\sock_client.py", line 130, in _sendall_with_error_handle
    sent = self._sock.send(data)
           ^^^^^^^^^^^^^^^^^^^^^
ConnectionAbortedError: [WinError 10053] An established connection was aborted by the software in your host machine
2025-03-09 19:47:57,818 INFO    MainThread:13900 [jupyter.py:save_ipynb():386] not saving jupyter notebook
2025-03-09 19:47:57,818 INFO    MainThread:13900 [wandb_init.py:_pause_backend():564] pausing backend
2025-03-09 19:47:57,818 ERROR   MainThread:13900 [redirect.py:_on_write():661] error in stdout callback
Traceback (most recent call last):
  File "C:\Users\prajv\AppData\Roaming\Python\Python312\site-packages\IPython\core\events.py", line 82, in trigger
    func(*args, **kwargs)
  File "c:\Python312\Lib\site-packages\wandb\sdk\wandb_init.py", line 565, in _pause_backend
    self.backend.interface.publish_pause()
  File "c:\Python312\Lib\site-packages\wandb\sdk\interface\interface.py", line 769, in publish_pause
    self._publish_pause(pause)
  File "c:\Python312\Lib\site-packages\wandb\sdk\interface\interface_shared.py", line 289, in _publish_pause
    self._publish(rec)
  File "c:\Python312\Lib\site-packages\wandb\sdk\interface\interface_sock.py", line 39, in _publish
    self._sock_client.send_record_publish(record)
  File "c:\Python312\Lib\site-packages\wandb\sdk\lib\sock_client.py", line 174, in send_record_publish
    self.send_server_request(server_req)
  File "c:\Python312\Lib\site-packages\wandb\sdk\lib\sock_client.py", line 154, in send_server_request
    self._send_message(msg)
  File "c:\Python312\Lib\site-packages\wandb\sdk\lib\sock_client.py", line 151, in _send_message
    self._sendall_with_error_handle(header + data)
  File "c:\Python312\Lib\site-packages\wandb\sdk\lib\sock_client.py", line 130, in _sendall_with_error_handle
    sent = self._sock.send(data)
           ^^^^^^^^^^^^^^^^^^^^^
ConnectionAbortedError: [WinError 10053] An established connection was aborted by the software in your host machine

During handling of the above exception, another exception occurred:

Traceback (most recent call last):
  File "c:\Python312\Lib\site-packages\wandb\sdk\lib\redirect.py", line 659, in _on_write
    cb(written_data)
  File "c:\Python312\Lib\site-packages\wandb\sdk\wandb_run.py", line 2296, in <lambda>
    lambda data: self._console_raw_callback("stdout", data),
                 ^^^^^^^^^^^^^^^^^^^^^^^^^^^^^^^^^^^^^^^^^^
  File "c:\Python312\Lib\site-packages\wandb\sdk\wandb_run.py", line 401, in wrapper_fn
    return func(self, *args, **kwargs)
           ^^^^^^^^^^^^^^^^^^^^^^^^^^^
  File "c:\Python312\Lib\site-packages\wandb\sdk\wandb_run.py", line 1444, in _console_raw_callback
    self._backend.interface.publish_output_raw(name, data)
  File "c:\Python312\Lib\site-packages\wandb\sdk\interface\interface.py", line 761, in publish_output_raw
    self._publish_output_raw(o)
  File "c:\Python312\Lib\site-packages\wandb\sdk\interface\interface_shared.py", line 38, in _publish_output_raw
    self._publish(rec)
  File "c:\Python312\Lib\site-packages\wandb\sdk\interface\interface_sock.py", line 39, in _publish
    self._sock_client.send_record_publish(record)
  File "c:\Python312\Lib\site-packages\wandb\sdk\lib\sock_client.py", line 174, in send_record_publish
    self.send_server_request(server_req)
  File "c:\Python312\Lib\site-packages\wandb\sdk\lib\sock_client.py", line 154, in send_server_request
    self._send_message(msg)
  File "c:\Python312\Lib\site-packages\wandb\sdk\lib\sock_client.py", line 151, in _send_message
    self._sendall_with_error_handle(header + data)
  File "c:\Python312\Lib\site-packages\wandb\sdk\lib\sock_client.py", line 130, in _sendall_with_error_handle
    sent = self._sock.send(data)
           ^^^^^^^^^^^^^^^^^^^^^
ConnectionAbortedError: [WinError 10053] An established connection was aborted by the software in your host machine
2025-03-09 19:47:57,818 ERROR   MainThread:13900 [redirect.py:_on_write():661] error in stdout callback
Traceback (most recent call last):
  File "C:\Users\prajv\AppData\Roaming\Python\Python312\site-packages\IPython\core\events.py", line 82, in trigger
    func(*args, **kwargs)
  File "c:\Python312\Lib\site-packages\wandb\sdk\wandb_init.py", line 565, in _pause_backend
    self.backend.interface.publish_pause()
  File "c:\Python312\Lib\site-packages\wandb\sdk\interface\interface.py", line 769, in publish_pause
    self._publish_pause(pause)
  File "c:\Python312\Lib\site-packages\wandb\sdk\interface\interface_shared.py", line 289, in _publish_pause
    self._publish(rec)
  File "c:\Python312\Lib\site-packages\wandb\sdk\interface\interface_sock.py", line 39, in _publish
    self._sock_client.send_record_publish(record)
  File "c:\Python312\Lib\site-packages\wandb\sdk\lib\sock_client.py", line 174, in send_record_publish
    self.send_server_request(server_req)
  File "c:\Python312\Lib\site-packages\wandb\sdk\lib\sock_client.py", line 154, in send_server_request
    self._send_message(msg)
  File "c:\Python312\Lib\site-packages\wandb\sdk\lib\sock_client.py", line 151, in _send_message
    self._sendall_with_error_handle(header + data)
  File "c:\Python312\Lib\site-packages\wandb\sdk\lib\sock_client.py", line 130, in _sendall_with_error_handle
    sent = self._sock.send(data)
           ^^^^^^^^^^^^^^^^^^^^^
ConnectionAbortedError: [WinError 10053] An established connection was aborted by the software in your host machine

During handling of the above exception, another exception occurred:

Traceback (most recent call last):
  File "c:\Python312\Lib\site-packages\wandb\sdk\lib\redirect.py", line 659, in _on_write
    cb(written_data)
  File "c:\Python312\Lib\site-packages\wandb\sdk\wandb_run.py", line 2296, in <lambda>
    lambda data: self._console_raw_callback("stdout", data),
                 ^^^^^^^^^^^^^^^^^^^^^^^^^^^^^^^^^^^^^^^^^^
  File "c:\Python312\Lib\site-packages\wandb\sdk\wandb_run.py", line 401, in wrapper_fn
    return func(self, *args, **kwargs)
           ^^^^^^^^^^^^^^^^^^^^^^^^^^^
  File "c:\Python312\Lib\site-packages\wandb\sdk\wandb_run.py", line 1444, in _console_raw_callback
    self._backend.interface.publish_output_raw(name, data)
  File "c:\Python312\Lib\site-packages\wandb\sdk\interface\interface.py", line 761, in publish_output_raw
    self._publish_output_raw(o)
  File "c:\Python312\Lib\site-packages\wandb\sdk\interface\interface_shared.py", line 38, in _publish_output_raw
    self._publish(rec)
  File "c:\Python312\Lib\site-packages\wandb\sdk\interface\interface_sock.py", line 39, in _publish
    self._sock_client.send_record_publish(record)
  File "c:\Python312\Lib\site-packages\wandb\sdk\lib\sock_client.py", line 174, in send_record_publish
    self.send_server_request(server_req)
  File "c:\Python312\Lib\site-packages\wandb\sdk\lib\sock_client.py", line 154, in send_server_request
    self._send_message(msg)
  File "c:\Python312\Lib\site-packages\wandb\sdk\lib\sock_client.py", line 151, in _send_message
    self._sendall_with_error_handle(header + data)
  File "c:\Python312\Lib\site-packages\wandb\sdk\lib\sock_client.py", line 130, in _sendall_with_error_handle
    sent = self._sock.send(data)
           ^^^^^^^^^^^^^^^^^^^^^
ConnectionAbortedError: [WinError 10053] An established connection was aborted by the software in your host machine
2025-03-09 19:47:57,913 INFO    MainThread:13900 [wandb_init.py:_resume_backend():569] resuming backend
2025-03-09 19:47:57,915 ERROR   MainThread:13900 [redirect.py:_on_write():661] error in stdout callback
Traceback (most recent call last):
  File "C:\Users\prajv\AppData\Roaming\Python\Python312\site-packages\IPython\core\events.py", line 82, in trigger
    func(*args, **kwargs)
  File "c:\Python312\Lib\site-packages\wandb\sdk\wandb_init.py", line 570, in _resume_backend
    self.backend.interface.publish_resume()
  File "c:\Python312\Lib\site-packages\wandb\sdk\interface\interface.py", line 777, in publish_resume
    self._publish_resume(resume)
  File "c:\Python312\Lib\site-packages\wandb\sdk\interface\interface_shared.py", line 293, in _publish_resume
    self._publish(rec)
  File "c:\Python312\Lib\site-packages\wandb\sdk\interface\interface_sock.py", line 39, in _publish
    self._sock_client.send_record_publish(record)
  File "c:\Python312\Lib\site-packages\wandb\sdk\lib\sock_client.py", line 174, in send_record_publish
    self.send_server_request(server_req)
  File "c:\Python312\Lib\site-packages\wandb\sdk\lib\sock_client.py", line 154, in send_server_request
    self._send_message(msg)
  File "c:\Python312\Lib\site-packages\wandb\sdk\lib\sock_client.py", line 151, in _send_message
    self._sendall_with_error_handle(header + data)
  File "c:\Python312\Lib\site-packages\wandb\sdk\lib\sock_client.py", line 130, in _sendall_with_error_handle
    sent = self._sock.send(data)
           ^^^^^^^^^^^^^^^^^^^^^
ConnectionAbortedError: [WinError 10053] An established connection was aborted by the software in your host machine

During handling of the above exception, another exception occurred:

Traceback (most recent call last):
  File "c:\Python312\Lib\site-packages\wandb\sdk\lib\redirect.py", line 659, in _on_write
    cb(written_data)
  File "c:\Python312\Lib\site-packages\wandb\sdk\wandb_run.py", line 2296, in <lambda>
    lambda data: self._console_raw_callback("stdout", data),
                 ^^^^^^^^^^^^^^^^^^^^^^^^^^^^^^^^^^^^^^^^^^
  File "c:\Python312\Lib\site-packages\wandb\sdk\wandb_run.py", line 401, in wrapper_fn
    return func(self, *args, **kwargs)
           ^^^^^^^^^^^^^^^^^^^^^^^^^^^
  File "c:\Python312\Lib\site-packages\wandb\sdk\wandb_run.py", line 1444, in _console_raw_callback
    self._backend.interface.publish_output_raw(name, data)
  File "c:\Python312\Lib\site-packages\wandb\sdk\interface\interface.py", line 761, in publish_output_raw
    self._publish_output_raw(o)
  File "c:\Python312\Lib\site-packages\wandb\sdk\interface\interface_shared.py", line 38, in _publish_output_raw
    self._publish(rec)
  File "c:\Python312\Lib\site-packages\wandb\sdk\interface\interface_sock.py", line 39, in _publish
    self._sock_client.send_record_publish(record)
  File "c:\Python312\Lib\site-packages\wandb\sdk\lib\sock_client.py", line 174, in send_record_publish
    self.send_server_request(server_req)
  File "c:\Python312\Lib\site-packages\wandb\sdk\lib\sock_client.py", line 154, in send_server_request
    self._send_message(msg)
  File "c:\Python312\Lib\site-packages\wandb\sdk\lib\sock_client.py", line 151, in _send_message
    self._sendall_with_error_handle(header + data)
  File "c:\Python312\Lib\site-packages\wandb\sdk\lib\sock_client.py", line 130, in _sendall_with_error_handle
    sent = self._sock.send(data)
           ^^^^^^^^^^^^^^^^^^^^^
ConnectionAbortedError: [WinError 10053] An established connection was aborted by the software in your host machine
2025-03-09 19:47:57,916 ERROR   MainThread:13900 [redirect.py:_on_write():661] error in stdout callback
Traceback (most recent call last):
  File "C:\Users\prajv\AppData\Roaming\Python\Python312\site-packages\IPython\core\events.py", line 82, in trigger
    func(*args, **kwargs)
  File "c:\Python312\Lib\site-packages\wandb\sdk\wandb_init.py", line 570, in _resume_backend
    self.backend.interface.publish_resume()
  File "c:\Python312\Lib\site-packages\wandb\sdk\interface\interface.py", line 777, in publish_resume
    self._publish_resume(resume)
  File "c:\Python312\Lib\site-packages\wandb\sdk\interface\interface_shared.py", line 293, in _publish_resume
    self._publish(rec)
  File "c:\Python312\Lib\site-packages\wandb\sdk\interface\interface_sock.py", line 39, in _publish
    self._sock_client.send_record_publish(record)
  File "c:\Python312\Lib\site-packages\wandb\sdk\lib\sock_client.py", line 174, in send_record_publish
    self.send_server_request(server_req)
  File "c:\Python312\Lib\site-packages\wandb\sdk\lib\sock_client.py", line 154, in send_server_request
    self._send_message(msg)
  File "c:\Python312\Lib\site-packages\wandb\sdk\lib\sock_client.py", line 151, in _send_message
    self._sendall_with_error_handle(header + data)
  File "c:\Python312\Lib\site-packages\wandb\sdk\lib\sock_client.py", line 130, in _sendall_with_error_handle
    sent = self._sock.send(data)
           ^^^^^^^^^^^^^^^^^^^^^
ConnectionAbortedError: [WinError 10053] An established connection was aborted by the software in your host machine

During handling of the above exception, another exception occurred:

Traceback (most recent call last):
  File "c:\Python312\Lib\site-packages\wandb\sdk\lib\redirect.py", line 659, in _on_write
    cb(written_data)
  File "c:\Python312\Lib\site-packages\wandb\sdk\wandb_run.py", line 2296, in <lambda>
    lambda data: self._console_raw_callback("stdout", data),
                 ^^^^^^^^^^^^^^^^^^^^^^^^^^^^^^^^^^^^^^^^^^
  File "c:\Python312\Lib\site-packages\wandb\sdk\wandb_run.py", line 401, in wrapper_fn
    return func(self, *args, **kwargs)
           ^^^^^^^^^^^^^^^^^^^^^^^^^^^
  File "c:\Python312\Lib\site-packages\wandb\sdk\wandb_run.py", line 1444, in _console_raw_callback
    self._backend.interface.publish_output_raw(name, data)
  File "c:\Python312\Lib\site-packages\wandb\sdk\interface\interface.py", line 761, in publish_output_raw
    self._publish_output_raw(o)
  File "c:\Python312\Lib\site-packages\wandb\sdk\interface\interface_shared.py", line 38, in _publish_output_raw
    self._publish(rec)
  File "c:\Python312\Lib\site-packages\wandb\sdk\interface\interface_sock.py", line 39, in _publish
    self._sock_client.send_record_publish(record)
  File "c:\Python312\Lib\site-packages\wandb\sdk\lib\sock_client.py", line 174, in send_record_publish
    self.send_server_request(server_req)
  File "c:\Python312\Lib\site-packages\wandb\sdk\lib\sock_client.py", line 154, in send_server_request
    self._send_message(msg)
  File "c:\Python312\Lib\site-packages\wandb\sdk\lib\sock_client.py", line 151, in _send_message
    self._sendall_with_error_handle(header + data)
  File "c:\Python312\Lib\site-packages\wandb\sdk\lib\sock_client.py", line 130, in _sendall_with_error_handle
    sent = self._sock.send(data)
           ^^^^^^^^^^^^^^^^^^^^^
ConnectionAbortedError: [WinError 10053] An established connection was aborted by the software in your host machine
2025-03-09 19:47:58,009 INFO    MainThread:13900 [wandb_init.py:setup_run_log_directory():647] Logging user logs to c:\Users\prajv\Downloads\ass1\DA6401_ASSIGNMENT1\wandb\run-20250309_194757-49j2igg5\logs\debug.log
2025-03-09 19:47:58,009 INFO    MainThread:13900 [wandb_init.py:setup_run_log_directory():648] Logging internal logs to c:\Users\prajv\Downloads\ass1\DA6401_ASSIGNMENT1\wandb\run-20250309_194757-49j2igg5\logs\debug-internal.log
2025-03-09 19:47:58,009 INFO    MainThread:13900 [wandb_init.py:init():761] calling init triggers
2025-03-09 19:47:58,009 INFO    MainThread:13900 [wandb_init.py:init():766] wandb.init called with sweep_config: {}
config: {'_wandb': {}}
2025-03-09 19:47:58,009 INFO    MainThread:13900 [wandb_init.py:init():776] wandb.init() called while a run is active
2025-03-09 19:47:58,009 ERROR   MainThread:13900 [wandb_init.py:init():1478] error in wandb.init()
Traceback (most recent call last):
  File "c:\Python312\Lib\site-packages\wandb\sdk\wandb_init.py", line 1468, in init
    return wi.init(run_settings, run_config)
           ^^^^^^^^^^^^^^^^^^^^^^^^^^^^^^^^^
  File "c:\Python312\Lib\site-packages\wandb\sdk\wandb_init.py", line 779, in init
    with telemetry.context() as tel:
         ^^^^^^^^^^^^^^^^^^^
  File "c:\Python312\Lib\site-packages\wandb\sdk\lib\telemetry.py", line 42, in __exit__
    self._run._telemetry_callback(self._obj)
  File "c:\Python312\Lib\site-packages\wandb\sdk\wandb_run.py", line 749, in _telemetry_callback
    self._telemetry_flush()
  File "c:\Python312\Lib\site-packages\wandb\sdk\wandb_run.py", line 762, in _telemetry_flush
    self._backend.interface._publish_telemetry(self._telemetry_obj)
  File "c:\Python312\Lib\site-packages\wandb\sdk\interface\interface_shared.py", line 60, in _publish_telemetry
    self._publish(rec)
  File "c:\Python312\Lib\site-packages\wandb\sdk\interface\interface_sock.py", line 39, in _publish
    self._sock_client.send_record_publish(record)
  File "c:\Python312\Lib\site-packages\wandb\sdk\lib\sock_client.py", line 174, in send_record_publish
    self.send_server_request(server_req)
  File "c:\Python312\Lib\site-packages\wandb\sdk\lib\sock_client.py", line 154, in send_server_request
    self._send_message(msg)
  File "c:\Python312\Lib\site-packages\wandb\sdk\lib\sock_client.py", line 151, in _send_message
    self._sendall_with_error_handle(header + data)
  File "c:\Python312\Lib\site-packages\wandb\sdk\lib\sock_client.py", line 130, in _sendall_with_error_handle
    sent = self._sock.send(data)
           ^^^^^^^^^^^^^^^^^^^^^
ConnectionAbortedError: [WinError 10053] An established connection was aborted by the software in your host machine
2025-03-09 19:47:58,185 INFO    MainThread:13900 [jupyter.py:save_ipynb():386] not saving jupyter notebook
2025-03-09 19:47:58,185 INFO    MainThread:13900 [wandb_init.py:_pause_backend():564] pausing backend
2025-03-09 19:47:58,185 ERROR   MainThread:13900 [redirect.py:_on_write():661] error in stdout callback
Traceback (most recent call last):
  File "C:\Users\prajv\AppData\Roaming\Python\Python312\site-packages\IPython\core\events.py", line 82, in trigger
    func(*args, **kwargs)
  File "c:\Python312\Lib\site-packages\wandb\sdk\wandb_init.py", line 565, in _pause_backend
    self.backend.interface.publish_pause()
  File "c:\Python312\Lib\site-packages\wandb\sdk\interface\interface.py", line 769, in publish_pause
    self._publish_pause(pause)
  File "c:\Python312\Lib\site-packages\wandb\sdk\interface\interface_shared.py", line 289, in _publish_pause
    self._publish(rec)
  File "c:\Python312\Lib\site-packages\wandb\sdk\interface\interface_sock.py", line 39, in _publish
    self._sock_client.send_record_publish(record)
  File "c:\Python312\Lib\site-packages\wandb\sdk\lib\sock_client.py", line 174, in send_record_publish
    self.send_server_request(server_req)
  File "c:\Python312\Lib\site-packages\wandb\sdk\lib\sock_client.py", line 154, in send_server_request
    self._send_message(msg)
  File "c:\Python312\Lib\site-packages\wandb\sdk\lib\sock_client.py", line 151, in _send_message
    self._sendall_with_error_handle(header + data)
  File "c:\Python312\Lib\site-packages\wandb\sdk\lib\sock_client.py", line 130, in _sendall_with_error_handle
    sent = self._sock.send(data)
           ^^^^^^^^^^^^^^^^^^^^^
ConnectionAbortedError: [WinError 10053] An established connection was aborted by the software in your host machine

During handling of the above exception, another exception occurred:

Traceback (most recent call last):
  File "c:\Python312\Lib\site-packages\wandb\sdk\lib\redirect.py", line 659, in _on_write
    cb(written_data)
  File "c:\Python312\Lib\site-packages\wandb\sdk\wandb_run.py", line 2296, in <lambda>
    lambda data: self._console_raw_callback("stdout", data),
                 ^^^^^^^^^^^^^^^^^^^^^^^^^^^^^^^^^^^^^^^^^^
  File "c:\Python312\Lib\site-packages\wandb\sdk\wandb_run.py", line 401, in wrapper_fn
    return func(self, *args, **kwargs)
           ^^^^^^^^^^^^^^^^^^^^^^^^^^^
  File "c:\Python312\Lib\site-packages\wandb\sdk\wandb_run.py", line 1444, in _console_raw_callback
    self._backend.interface.publish_output_raw(name, data)
  File "c:\Python312\Lib\site-packages\wandb\sdk\interface\interface.py", line 761, in publish_output_raw
    self._publish_output_raw(o)
  File "c:\Python312\Lib\site-packages\wandb\sdk\interface\interface_shared.py", line 38, in _publish_output_raw
    self._publish(rec)
  File "c:\Python312\Lib\site-packages\wandb\sdk\interface\interface_sock.py", line 39, in _publish
    self._sock_client.send_record_publish(record)
  File "c:\Python312\Lib\site-packages\wandb\sdk\lib\sock_client.py", line 174, in send_record_publish
    self.send_server_request(server_req)
  File "c:\Python312\Lib\site-packages\wandb\sdk\lib\sock_client.py", line 154, in send_server_request
    self._send_message(msg)
  File "c:\Python312\Lib\site-packages\wandb\sdk\lib\sock_client.py", line 151, in _send_message
    self._sendall_with_error_handle(header + data)
  File "c:\Python312\Lib\site-packages\wandb\sdk\lib\sock_client.py", line 130, in _sendall_with_error_handle
    sent = self._sock.send(data)
           ^^^^^^^^^^^^^^^^^^^^^
ConnectionAbortedError: [WinError 10053] An established connection was aborted by the software in your host machine
2025-03-09 19:47:58,200 ERROR   MainThread:13900 [redirect.py:_on_write():661] error in stdout callback
Traceback (most recent call last):
  File "C:\Users\prajv\AppData\Roaming\Python\Python312\site-packages\IPython\core\events.py", line 82, in trigger
    func(*args, **kwargs)
  File "c:\Python312\Lib\site-packages\wandb\sdk\wandb_init.py", line 565, in _pause_backend
    self.backend.interface.publish_pause()
  File "c:\Python312\Lib\site-packages\wandb\sdk\interface\interface.py", line 769, in publish_pause
    self._publish_pause(pause)
  File "c:\Python312\Lib\site-packages\wandb\sdk\interface\interface_shared.py", line 289, in _publish_pause
    self._publish(rec)
  File "c:\Python312\Lib\site-packages\wandb\sdk\interface\interface_sock.py", line 39, in _publish
    self._sock_client.send_record_publish(record)
  File "c:\Python312\Lib\site-packages\wandb\sdk\lib\sock_client.py", line 174, in send_record_publish
    self.send_server_request(server_req)
  File "c:\Python312\Lib\site-packages\wandb\sdk\lib\sock_client.py", line 154, in send_server_request
    self._send_message(msg)
  File "c:\Python312\Lib\site-packages\wandb\sdk\lib\sock_client.py", line 151, in _send_message
    self._sendall_with_error_handle(header + data)
  File "c:\Python312\Lib\site-packages\wandb\sdk\lib\sock_client.py", line 130, in _sendall_with_error_handle
    sent = self._sock.send(data)
           ^^^^^^^^^^^^^^^^^^^^^
ConnectionAbortedError: [WinError 10053] An established connection was aborted by the software in your host machine

During handling of the above exception, another exception occurred:

Traceback (most recent call last):
  File "c:\Python312\Lib\site-packages\wandb\sdk\lib\redirect.py", line 659, in _on_write
    cb(written_data)
  File "c:\Python312\Lib\site-packages\wandb\sdk\wandb_run.py", line 2296, in <lambda>
    lambda data: self._console_raw_callback("stdout", data),
                 ^^^^^^^^^^^^^^^^^^^^^^^^^^^^^^^^^^^^^^^^^^
  File "c:\Python312\Lib\site-packages\wandb\sdk\wandb_run.py", line 401, in wrapper_fn
    return func(self, *args, **kwargs)
           ^^^^^^^^^^^^^^^^^^^^^^^^^^^
  File "c:\Python312\Lib\site-packages\wandb\sdk\wandb_run.py", line 1444, in _console_raw_callback
    self._backend.interface.publish_output_raw(name, data)
  File "c:\Python312\Lib\site-packages\wandb\sdk\interface\interface.py", line 761, in publish_output_raw
    self._publish_output_raw(o)
  File "c:\Python312\Lib\site-packages\wandb\sdk\interface\interface_shared.py", line 38, in _publish_output_raw
    self._publish(rec)
  File "c:\Python312\Lib\site-packages\wandb\sdk\interface\interface_sock.py", line 39, in _publish
    self._sock_client.send_record_publish(record)
  File "c:\Python312\Lib\site-packages\wandb\sdk\lib\sock_client.py", line 174, in send_record_publish
    self.send_server_request(server_req)
  File "c:\Python312\Lib\site-packages\wandb\sdk\lib\sock_client.py", line 154, in send_server_request
    self._send_message(msg)
  File "c:\Python312\Lib\site-packages\wandb\sdk\lib\sock_client.py", line 151, in _send_message
    self._sendall_with_error_handle(header + data)
  File "c:\Python312\Lib\site-packages\wandb\sdk\lib\sock_client.py", line 130, in _sendall_with_error_handle
    sent = self._sock.send(data)
           ^^^^^^^^^^^^^^^^^^^^^
ConnectionAbortedError: [WinError 10053] An established connection was aborted by the software in your host machine
2025-03-09 19:48:18,837 INFO    MainThread:13900 [wandb_init.py:_resume_backend():569] resuming backend
2025-03-09 19:48:18,837 ERROR   MainThread:13900 [redirect.py:_on_write():661] error in stdout callback
Traceback (most recent call last):
  File "C:\Users\prajv\AppData\Roaming\Python\Python312\site-packages\IPython\core\events.py", line 82, in trigger
    func(*args, **kwargs)
  File "c:\Python312\Lib\site-packages\wandb\sdk\wandb_init.py", line 570, in _resume_backend
    self.backend.interface.publish_resume()
  File "c:\Python312\Lib\site-packages\wandb\sdk\interface\interface.py", line 777, in publish_resume
    self._publish_resume(resume)
  File "c:\Python312\Lib\site-packages\wandb\sdk\interface\interface_shared.py", line 293, in _publish_resume
    self._publish(rec)
  File "c:\Python312\Lib\site-packages\wandb\sdk\interface\interface_sock.py", line 39, in _publish
    self._sock_client.send_record_publish(record)
  File "c:\Python312\Lib\site-packages\wandb\sdk\lib\sock_client.py", line 174, in send_record_publish
    self.send_server_request(server_req)
  File "c:\Python312\Lib\site-packages\wandb\sdk\lib\sock_client.py", line 154, in send_server_request
    self._send_message(msg)
  File "c:\Python312\Lib\site-packages\wandb\sdk\lib\sock_client.py", line 151, in _send_message
    self._sendall_with_error_handle(header + data)
  File "c:\Python312\Lib\site-packages\wandb\sdk\lib\sock_client.py", line 130, in _sendall_with_error_handle
    sent = self._sock.send(data)
           ^^^^^^^^^^^^^^^^^^^^^
ConnectionAbortedError: [WinError 10053] An established connection was aborted by the software in your host machine

During handling of the above exception, another exception occurred:

Traceback (most recent call last):
  File "c:\Python312\Lib\site-packages\wandb\sdk\lib\redirect.py", line 659, in _on_write
    cb(written_data)
  File "c:\Python312\Lib\site-packages\wandb\sdk\wandb_run.py", line 2296, in <lambda>
    lambda data: self._console_raw_callback("stdout", data),
                 ^^^^^^^^^^^^^^^^^^^^^^^^^^^^^^^^^^^^^^^^^^
  File "c:\Python312\Lib\site-packages\wandb\sdk\wandb_run.py", line 401, in wrapper_fn
    return func(self, *args, **kwargs)
           ^^^^^^^^^^^^^^^^^^^^^^^^^^^
  File "c:\Python312\Lib\site-packages\wandb\sdk\wandb_run.py", line 1444, in _console_raw_callback
    self._backend.interface.publish_output_raw(name, data)
  File "c:\Python312\Lib\site-packages\wandb\sdk\interface\interface.py", line 761, in publish_output_raw
    self._publish_output_raw(o)
  File "c:\Python312\Lib\site-packages\wandb\sdk\interface\interface_shared.py", line 38, in _publish_output_raw
    self._publish(rec)
  File "c:\Python312\Lib\site-packages\wandb\sdk\interface\interface_sock.py", line 39, in _publish
    self._sock_client.send_record_publish(record)
  File "c:\Python312\Lib\site-packages\wandb\sdk\lib\sock_client.py", line 174, in send_record_publish
    self.send_server_request(server_req)
  File "c:\Python312\Lib\site-packages\wandb\sdk\lib\sock_client.py", line 154, in send_server_request
    self._send_message(msg)
  File "c:\Python312\Lib\site-packages\wandb\sdk\lib\sock_client.py", line 151, in _send_message
    self._sendall_with_error_handle(header + data)
  File "c:\Python312\Lib\site-packages\wandb\sdk\lib\sock_client.py", line 130, in _sendall_with_error_handle
    sent = self._sock.send(data)
           ^^^^^^^^^^^^^^^^^^^^^
ConnectionAbortedError: [WinError 10053] An established connection was aborted by the software in your host machine
2025-03-09 19:48:18,839 ERROR   MainThread:13900 [redirect.py:_on_write():661] error in stdout callback
Traceback (most recent call last):
  File "C:\Users\prajv\AppData\Roaming\Python\Python312\site-packages\IPython\core\events.py", line 82, in trigger
    func(*args, **kwargs)
  File "c:\Python312\Lib\site-packages\wandb\sdk\wandb_init.py", line 570, in _resume_backend
    self.backend.interface.publish_resume()
  File "c:\Python312\Lib\site-packages\wandb\sdk\interface\interface.py", line 777, in publish_resume
    self._publish_resume(resume)
  File "c:\Python312\Lib\site-packages\wandb\sdk\interface\interface_shared.py", line 293, in _publish_resume
    self._publish(rec)
  File "c:\Python312\Lib\site-packages\wandb\sdk\interface\interface_sock.py", line 39, in _publish
    self._sock_client.send_record_publish(record)
  File "c:\Python312\Lib\site-packages\wandb\sdk\lib\sock_client.py", line 174, in send_record_publish
    self.send_server_request(server_req)
  File "c:\Python312\Lib\site-packages\wandb\sdk\lib\sock_client.py", line 154, in send_server_request
    self._send_message(msg)
  File "c:\Python312\Lib\site-packages\wandb\sdk\lib\sock_client.py", line 151, in _send_message
    self._sendall_with_error_handle(header + data)
  File "c:\Python312\Lib\site-packages\wandb\sdk\lib\sock_client.py", line 130, in _sendall_with_error_handle
    sent = self._sock.send(data)
           ^^^^^^^^^^^^^^^^^^^^^
ConnectionAbortedError: [WinError 10053] An established connection was aborted by the software in your host machine

During handling of the above exception, another exception occurred:

Traceback (most recent call last):
  File "c:\Python312\Lib\site-packages\wandb\sdk\lib\redirect.py", line 659, in _on_write
    cb(written_data)
  File "c:\Python312\Lib\site-packages\wandb\sdk\wandb_run.py", line 2296, in <lambda>
    lambda data: self._console_raw_callback("stdout", data),
                 ^^^^^^^^^^^^^^^^^^^^^^^^^^^^^^^^^^^^^^^^^^
  File "c:\Python312\Lib\site-packages\wandb\sdk\wandb_run.py", line 401, in wrapper_fn
    return func(self, *args, **kwargs)
           ^^^^^^^^^^^^^^^^^^^^^^^^^^^
  File "c:\Python312\Lib\site-packages\wandb\sdk\wandb_run.py", line 1444, in _console_raw_callback
    self._backend.interface.publish_output_raw(name, data)
  File "c:\Python312\Lib\site-packages\wandb\sdk\interface\interface.py", line 761, in publish_output_raw
    self._publish_output_raw(o)
  File "c:\Python312\Lib\site-packages\wandb\sdk\interface\interface_shared.py", line 38, in _publish_output_raw
    self._publish(rec)
  File "c:\Python312\Lib\site-packages\wandb\sdk\interface\interface_sock.py", line 39, in _publish
    self._sock_client.send_record_publish(record)
  File "c:\Python312\Lib\site-packages\wandb\sdk\lib\sock_client.py", line 174, in send_record_publish
    self.send_server_request(server_req)
  File "c:\Python312\Lib\site-packages\wandb\sdk\lib\sock_client.py", line 154, in send_server_request
    self._send_message(msg)
  File "c:\Python312\Lib\site-packages\wandb\sdk\lib\sock_client.py", line 151, in _send_message
    self._sendall_with_error_handle(header + data)
  File "c:\Python312\Lib\site-packages\wandb\sdk\lib\sock_client.py", line 130, in _sendall_with_error_handle
    sent = self._sock.send(data)
           ^^^^^^^^^^^^^^^^^^^^^
ConnectionAbortedError: [WinError 10053] An established connection was aborted by the software in your host machine
2025-03-09 19:48:18,907 INFO    MainThread:13900 [jupyter.py:save_ipynb():386] not saving jupyter notebook
2025-03-09 19:48:18,907 INFO    MainThread:13900 [wandb_init.py:_pause_backend():564] pausing backend
2025-03-09 19:48:18,907 ERROR   MainThread:13900 [redirect.py:_on_write():661] error in stdout callback
Traceback (most recent call last):
  File "C:\Users\prajv\AppData\Roaming\Python\Python312\site-packages\IPython\core\events.py", line 82, in trigger
    func(*args, **kwargs)
  File "c:\Python312\Lib\site-packages\wandb\sdk\wandb_init.py", line 565, in _pause_backend
    self.backend.interface.publish_pause()
  File "c:\Python312\Lib\site-packages\wandb\sdk\interface\interface.py", line 769, in publish_pause
    self._publish_pause(pause)
  File "c:\Python312\Lib\site-packages\wandb\sdk\interface\interface_shared.py", line 289, in _publish_pause
    self._publish(rec)
  File "c:\Python312\Lib\site-packages\wandb\sdk\interface\interface_sock.py", line 39, in _publish
    self._sock_client.send_record_publish(record)
  File "c:\Python312\Lib\site-packages\wandb\sdk\lib\sock_client.py", line 174, in send_record_publish
    self.send_server_request(server_req)
  File "c:\Python312\Lib\site-packages\wandb\sdk\lib\sock_client.py", line 154, in send_server_request
    self._send_message(msg)
  File "c:\Python312\Lib\site-packages\wandb\sdk\lib\sock_client.py", line 151, in _send_message
    self._sendall_with_error_handle(header + data)
  File "c:\Python312\Lib\site-packages\wandb\sdk\lib\sock_client.py", line 130, in _sendall_with_error_handle
    sent = self._sock.send(data)
           ^^^^^^^^^^^^^^^^^^^^^
ConnectionAbortedError: [WinError 10053] An established connection was aborted by the software in your host machine

During handling of the above exception, another exception occurred:

Traceback (most recent call last):
  File "c:\Python312\Lib\site-packages\wandb\sdk\lib\redirect.py", line 659, in _on_write
    cb(written_data)
  File "c:\Python312\Lib\site-packages\wandb\sdk\wandb_run.py", line 2296, in <lambda>
    lambda data: self._console_raw_callback("stdout", data),
                 ^^^^^^^^^^^^^^^^^^^^^^^^^^^^^^^^^^^^^^^^^^
  File "c:\Python312\Lib\site-packages\wandb\sdk\wandb_run.py", line 401, in wrapper_fn
    return func(self, *args, **kwargs)
           ^^^^^^^^^^^^^^^^^^^^^^^^^^^
  File "c:\Python312\Lib\site-packages\wandb\sdk\wandb_run.py", line 1444, in _console_raw_callback
    self._backend.interface.publish_output_raw(name, data)
  File "c:\Python312\Lib\site-packages\wandb\sdk\interface\interface.py", line 761, in publish_output_raw
    self._publish_output_raw(o)
  File "c:\Python312\Lib\site-packages\wandb\sdk\interface\interface_shared.py", line 38, in _publish_output_raw
    self._publish(rec)
  File "c:\Python312\Lib\site-packages\wandb\sdk\interface\interface_sock.py", line 39, in _publish
    self._sock_client.send_record_publish(record)
  File "c:\Python312\Lib\site-packages\wandb\sdk\lib\sock_client.py", line 174, in send_record_publish
    self.send_server_request(server_req)
  File "c:\Python312\Lib\site-packages\wandb\sdk\lib\sock_client.py", line 154, in send_server_request
    self._send_message(msg)
  File "c:\Python312\Lib\site-packages\wandb\sdk\lib\sock_client.py", line 151, in _send_message
    self._sendall_with_error_handle(header + data)
  File "c:\Python312\Lib\site-packages\wandb\sdk\lib\sock_client.py", line 130, in _sendall_with_error_handle
    sent = self._sock.send(data)
           ^^^^^^^^^^^^^^^^^^^^^
ConnectionAbortedError: [WinError 10053] An established connection was aborted by the software in your host machine
2025-03-09 19:48:18,922 ERROR   MainThread:13900 [redirect.py:_on_write():661] error in stdout callback
Traceback (most recent call last):
  File "C:\Users\prajv\AppData\Roaming\Python\Python312\site-packages\IPython\core\events.py", line 82, in trigger
    func(*args, **kwargs)
  File "c:\Python312\Lib\site-packages\wandb\sdk\wandb_init.py", line 565, in _pause_backend
    self.backend.interface.publish_pause()
  File "c:\Python312\Lib\site-packages\wandb\sdk\interface\interface.py", line 769, in publish_pause
    self._publish_pause(pause)
  File "c:\Python312\Lib\site-packages\wandb\sdk\interface\interface_shared.py", line 289, in _publish_pause
    self._publish(rec)
  File "c:\Python312\Lib\site-packages\wandb\sdk\interface\interface_sock.py", line 39, in _publish
    self._sock_client.send_record_publish(record)
  File "c:\Python312\Lib\site-packages\wandb\sdk\lib\sock_client.py", line 174, in send_record_publish
    self.send_server_request(server_req)
  File "c:\Python312\Lib\site-packages\wandb\sdk\lib\sock_client.py", line 154, in send_server_request
    self._send_message(msg)
  File "c:\Python312\Lib\site-packages\wandb\sdk\lib\sock_client.py", line 151, in _send_message
    self._sendall_with_error_handle(header + data)
  File "c:\Python312\Lib\site-packages\wandb\sdk\lib\sock_client.py", line 130, in _sendall_with_error_handle
    sent = self._sock.send(data)
           ^^^^^^^^^^^^^^^^^^^^^
ConnectionAbortedError: [WinError 10053] An established connection was aborted by the software in your host machine

During handling of the above exception, another exception occurred:

Traceback (most recent call last):
  File "c:\Python312\Lib\site-packages\wandb\sdk\lib\redirect.py", line 659, in _on_write
    cb(written_data)
  File "c:\Python312\Lib\site-packages\wandb\sdk\wandb_run.py", line 2296, in <lambda>
    lambda data: self._console_raw_callback("stdout", data),
                 ^^^^^^^^^^^^^^^^^^^^^^^^^^^^^^^^^^^^^^^^^^
  File "c:\Python312\Lib\site-packages\wandb\sdk\wandb_run.py", line 401, in wrapper_fn
    return func(self, *args, **kwargs)
           ^^^^^^^^^^^^^^^^^^^^^^^^^^^
  File "c:\Python312\Lib\site-packages\wandb\sdk\wandb_run.py", line 1444, in _console_raw_callback
    self._backend.interface.publish_output_raw(name, data)
  File "c:\Python312\Lib\site-packages\wandb\sdk\interface\interface.py", line 761, in publish_output_raw
    self._publish_output_raw(o)
  File "c:\Python312\Lib\site-packages\wandb\sdk\interface\interface_shared.py", line 38, in _publish_output_raw
    self._publish(rec)
  File "c:\Python312\Lib\site-packages\wandb\sdk\interface\interface_sock.py", line 39, in _publish
    self._sock_client.send_record_publish(record)
  File "c:\Python312\Lib\site-packages\wandb\sdk\lib\sock_client.py", line 174, in send_record_publish
    self.send_server_request(server_req)
  File "c:\Python312\Lib\site-packages\wandb\sdk\lib\sock_client.py", line 154, in send_server_request
    self._send_message(msg)
  File "c:\Python312\Lib\site-packages\wandb\sdk\lib\sock_client.py", line 151, in _send_message
    self._sendall_with_error_handle(header + data)
  File "c:\Python312\Lib\site-packages\wandb\sdk\lib\sock_client.py", line 130, in _sendall_with_error_handle
    sent = self._sock.send(data)
           ^^^^^^^^^^^^^^^^^^^^^
ConnectionAbortedError: [WinError 10053] An established connection was aborted by the software in your host machine
