2025-03-09 22:06:30,029 INFO    Thread-21 (_run_job):10656 [wandb_init.py:setup_run_log_directory():647] Logging user logs to c:\Users\prajv\Downloads\ass1\DA6401_ASSIGNMENT1\wandb\run-20250309_220630-ycbce2mh\logs\debug.log
2025-03-09 22:06:30,029 INFO    Thread-21 (_run_job):10656 [wandb_init.py:setup_run_log_directory():648] Logging internal logs to c:\Users\prajv\Downloads\ass1\DA6401_ASSIGNMENT1\wandb\run-20250309_220630-ycbce2mh\logs\debug-internal.log
2025-03-09 22:06:30,029 INFO    Thread-21 (_run_job):10656 [wandb_init.py:init():761] calling init triggers
2025-03-09 22:06:30,029 INFO    Thread-21 (_run_job):10656 [wandb_init.py:init():766] wandb.init called with sweep_config: {'activationFunc': 'tanh', 'batchSize': 16, 'hiddenLayer_Size': 128, 'learningRate': 0.0001, 'num_epochs': 20, 'num_hiddenLayers': 3, 'optimizer': 'momentum', 'weightDecay': 0, 'weightInit': 'random'}
config: {'num_epochs': 10, 'num_hiddenLayers': 3, 'hiddenLayer_Size': 40, 'weightDecay': 0, 'learningRate': 0.001, 'optimizer': 'Nesterov_Accelerated_GD', 'batchSize': 32, 'weightInit': 'xavier', 'activationFunc': 'sigmoid', '_wandb': {}}
2025-03-09 22:06:30,033 INFO    Thread-21 (_run_job):10656 [wandb_init.py:init():776] wandb.init() called while a run is active
2025-03-09 22:06:30,176 INFO    Thread-21 (_run_job):10656 [wandb_run.py:_finish():2112] finishing run da6401-assignments/assignment1/ycbce2mh
2025-03-09 22:06:30,180 ERROR   Thread-21 (_run_job):10656 [jupyter.py:save_history():450] Run pip install nbformat to save notebook history
2025-03-09 22:06:30,180 INFO    Thread-21 (_run_job):10656 [jupyter.py:save_ipynb():386] not saving jupyter notebook
2025-03-09 22:06:30,180 INFO    Thread-21 (_run_job):10656 [wandb_init.py:_jupyter_teardown():581] cleaning up jupyter logic
2025-03-09 22:06:30,181 INFO    Thread-21 (_run_job):10656 [wandb_run.py:_atexit_cleanup():2340] got exitcode: 1
2025-03-09 22:06:30,181 INFO    Thread-21 (_run_job):10656 [wandb_run.py:_restore():2322] restore
2025-03-09 22:06:30,182 INFO    Thread-21 (_run_job):10656 [wandb_run.py:_restore():2328] restore done
2025-03-09 22:06:32,259 INFO    Thread-21 (_run_job):10656 [wandb_run.py:_footer_history_summary_info():3956] rendering history
2025-03-09 22:06:32,259 INFO    Thread-21 (_run_job):10656 [wandb_run.py:_footer_history_summary_info():3988] rendering summary
2025-03-09 22:06:32,259 INFO    Thread-21 (_run_job):10656 [wandb_run.py:_footer_sync_info():3917] logging synced files
2025-03-09 22:06:32,263 ERROR   MainThread:10656 [pyagent.py:_run_jobs_from_queue():234] Run ycbce2mh errored:
Traceback (most recent call last):
  File "c:\Python312\Lib\site-packages\wandb\agents\pyagent.py", line 306, in _run_job
    self._function()
  File "C:\Users\prajv\AppData\Local\Temp\ipykernel_10656\1058529509.py", line 36, in sweep_hyperParameters
    model.train(x_train, y_train, x_val, y_val, num_epochs, learningRate, optimizer, batchSize)
  File "C:\Users\prajv\AppData\Local\Temp\ipykernel_10656\2685923661.py", line 60, in train
    self.forward(x_batch)
  File "C:\Users\prajv\AppData\Local\Temp\ipykernel_10656\2685923661.py", line 107, in forward
    x = self.sigmoid(np.dot(x, w) + b)
                     ^^^^^^^^^^^^
ValueError: shapes (784,16) and (784,128) not aligned: 16 (dim 1) != 784 (dim 0)

2025-03-09 22:06:32,263 ERROR   MainThread:10656 [pyagent.py:_run_jobs_from_queue():245] Detected 3 failed runs in the first 60 seconds, killing sweep.
